<robot xmlns:xacro="http://www.ros.org/wiki/xacro" name="catapulta">
  <material name="green">
    <color rgba="0 0.4 0.2 1"/>
  </material>
  <material name="dark_green">
    <color rgba="0 0.05 0 1"/>
  </material>
  <material name="light_green">
    <color rgba="0.9 1.0 0.9 1"/>
  </material>
  <material name="black">
    <color rgba="0 0 0 1"/>
  </material>
  <material name="Cyan1">
    <color rgba="0 0.9 0.9 1.0"/>
  </material>

  <xacro:property name="h" value="0.32"/>
  <xacro:property name="w" value="0.26"/>
  <xacro:property name="d" value="0.065"/>

  <xacro:property name="basis_fixed_size_1" value="0.32"/>
  <xacro:property name="basis_fixed_size_2" value="0.05"/>
  <xacro:property name="basis_fixed_size_3" value="0.22"/>
  
 	<link name="base_link">
		<visual>
		    <origin xyz="0 0 0" rpy="0 0 0"/>
			<geometry>
				<box size="${h} ${w} ${d}"/>
			</geometry>
			<material name="dark_green"/>
		</visual>	
    <collision>
      <geometry>
        <box size="${h} ${w} ${d}"/>
      </geometry>
    </collision>
    <inertial>
      <mass value="5"/>
      <inertia ixx="${1 / 12 * 5 * (h * w + d * d)}" 
               ixy="0.0" 
               ixz="0.0" 
               iyy="${1 / 12 * 5 * (h * h + d * d)}" 
               iyz="0.0" 
               izz="${1 / 12 * 5 * (w * w + h * h)}"/>
    </inertial>
	</link>

  <xacro:macro name="make_parallelepiped" params="name h w d color mass">
		<link name="${name}">
			<visual>
				<geometry>
					<box size="${h} ${w} ${d}"/>
				</geometry>
				<material name="${color}"/>
			</visual>
			<collision>
				<geometry>
					<box size="${h} ${w} ${d}"/>
				</geometry>
			</collision>
			<inertial>
				<mass value="${mass}"/>
        <inertia ixx="${mass / 12 * (w * w + d * d)}" 
          ixy="0.0" 
          ixz="0.0" 
          iyy="${1 / 12 * mass * (h * h + d * d)}" 
          iyz="0.0" 
          izz="${1 / 12 * mass * (w * w + h * h)}"/>
			</inertial>	
		</link>
	</xacro:macro>

  <xacro:macro name="make_cylinder" params="name radius length color mass">
		<link name="${name}">
			<visual>
				<geometry>
					<cylinder radius="${radius}" length="${length}"/>
				</geometry>
				<material name="${color}"/>
			</visual>
			<collision>
				<geometry>
					<cylinder radius="${radius}" length="${length}"/>
				</geometry>
			</collision>
			<inertial>
				<mass value="${mass}"/>
				<inertia ixx="${(mass/12)*((3*radius*radius)+(length*length))}" 
						 ixy="0" 
						 ixz="0" 
						 iyy="${(mass/12)*((3*radius*radius)+(length*length))}" 
						 iyz="0" 
						 izz="${(mass/2)*(radius*radius)}"/>
			</inertial>	
		</link>
	</xacro:macro>

  <xacro:macro name="joint" params="parent child type xyz rpy">
		<joint name="${parent}_${child}_joint" type="${type}">
			<parent link="${parent}"/>
			<child link="${child}"/>
			<origin xyz="${xyz}" rpy="${rpy}"/>
		</joint>
	</xacro:macro>
	
	<xacro:macro name="drive_joint" params="parent child type xyz rpy axis">
		<joint name="${parent}_${child}_joint" type="${type}">
			<parent link="${parent}_link"/>
			<child link="${child}_link"/>
			<origin xyz="${xyz}" rpy="${rpy}"/>
			<axis xyz="${axis}"/>
		</joint>
	</xacro:macro>

  <xacro:make_parallelepiped name="basis1"
            h="${h}"
            w="${basis_fixed_size_2}"
            d="${basis_fixed_size_2}"
            color="Cyan1"
            mass="0.5" />

  <xacro:make_parallelepiped name="basis2"
            h="${basis_fixed_size_2}"
            w="${basis_fixed_size_2}"
            d="${basis_fixed_size_3}"
            color="Cyan1"
            mass="0.5" />

  <xacro:make_parallelepiped name="basis3"
            h="${h}"
            w="${basis_fixed_size_2}"
            d="${basis_fixed_size_2}"
            color="Cyan1"
            mass="0.5" />

  <xacro:make_parallelepiped name="basis4"
            h="${basis_fixed_size_2}"
            w="${basis_fixed_size_2}"
            d="${basis_fixed_size_3}"
            color="Cyan1"
            mass="0.5" />

  <xacro:make_parallelepiped name="basis5"
            h="${basis_fixed_size_2}"
            w="${basis_fixed_size_3}"
            d="${basis_fixed_size_2}"
            color="Cyan1"
            mass="0.5" />

  <xacro:make_parallelepiped name="basis6"
            h="${basis_fixed_size_2}"
            w="${basis_fixed_size_3}"
            d="${basis_fixed_size_2}"
            color="Cyan1"
            mass="0.5" />

  <xacro:make_parallelepiped name="basis7"
            h="${basis_fixed_size_2}"
            w="${basis_fixed_size_3}"
            d="${basis_fixed_size_2}"
            color="Cyan1"
            mass="0.5" />

  <xacro:make_parallelepiped name="basis8"
            h="${basis_fixed_size_2}"
            w="0.27"
            d="0.005"
            color="Cyan1"
            mass="0.5" />

  <xacro:make_cylinder name="basis9" 
            radius="0.03" length="0.02" 
            color="dark_green" 
            mass="0.1" />

  <xacro:make_cylinder name="basis10" 
            radius="0.01" length="0.1" 
            color="black" 
            mass="0.1" />

  <xacro:make_cylinder name="basis11" 
            radius="0.01" length="0.05" 
            color="black" 
            mass="0.1" />

	<xacro:make_cylinder name="right_drive_link" 
						 radius="0.04" length="0.02" 
						 color="black" 
						 mass="0.1" />

	<xacro:make_cylinder name="left_drive_link" 
						 radius="0.04" length="0.02" 
						 color="black" 
						 mass="0.1" />

  <link name="front_driven_link">
    <visual>
      <geometry>
        <sphere radius="0.037"/>
      </geometry>
      <material name="black"/>
    </visual>
    <collision>
      <geometry>
        <sphere radius="0.037"/>
      </geometry>
    </collision>
    <inertial>
      <mass value="0.1"/>
      <inertia ixx="${2 / 10 * 0.037 * 0.037}" 
               ixy="0.0" 
               ixz="0.0" 
               iyy="${2 / 10 * 0.037 * 0.037}"
               iyz="0.0" 
               izz="${2 / 10 * 0.037 * 0.037}"/>
    </inertial>
  </link>

  <xacro:joint parent="base_link" child="basis1"
      type="fixed"
      xyz="0 0.1 0.06" rpy="0 0 0"/>

  <xacro:joint parent="base_link" child="basis2"
      type="fixed"
      xyz="0 -0.1 0.16" rpy="0 0 0"/>

  <xacro:joint parent="base_link" child="basis3"
      type="fixed"
      xyz="0 -0.1 0.06" rpy="0 0 0"/>

  <xacro:joint parent="base_link" child="basis4"
      type="fixed"
      xyz="0 0.1 0.16" rpy="0 0 0"/>

  <xacro:joint parent="base_link" child="basis5"
      type="fixed"
      xyz="0.1 0 0.06" rpy="0 0 0"/>

  <xacro:joint parent="base_link" child="basis6"
      type="fixed"
      xyz="-0.1 0 0.06" rpy="0 0 0"/>

  <xacro:joint parent="base_link" child="basis7"
      type="fixed"
      xyz="-0 0 0.23" rpy="0 0 0"/>

  <xacro:joint parent="base_link" child="basis8"
      type="fixed"
      xyz="-0.03 0 0.13" rpy="0.37 0 1.57"/>

  <xacro:joint parent="base_link" child="basis9"
      type="fixed"
      xyz="-0.16 0 0.184" rpy="0.37 0 1.57"/>

  <xacro:joint parent="base_link" child="basis10"
      type="fixed"
      xyz="-0.06 0 0.188" rpy="0.67 0 1.57"/>

  <xacro:joint parent="base_link" child="basis11"
      type="fixed"
      xyz="0.1 0 0.081" rpy="1.57 0 0"/>

  <joint name="right_drive_joint" type="continuous">
    <parent link="base_link"/>
    <child link="right_drive_link"/>
    <origin xyz="-0.1 -0.14 -0.02" rpy="1.57 0 0"/>
    <axis xyz="0 0 -2"/>
  </joint>

  <joint name="left_drive_joint" type="continuous">
    <parent link="base_link"/>
    <child link="left_drive_link"/>
    <origin xyz="-0.1 0.14 -0.02" rpy="1.57 0 0"/>
    <axis xyz="0 0 -2"/>
  </joint>

  <joint name="base_driven_joint" type="fixed">
    <parent link="base_link"/>
    <child link="front_driven_link"/>
    <origin xyz="0.1 0 -0.02" rpy="0 0 0"/>
  </joint>

  <gazebo reference="front_driven_link">
    <mu1 value="0.001"/>
    <mu2 value="0.001"/>
  </gazebo>
  
  <gazebo>
    <plugin
      filename="gz-sim-joint-state-publisher-system"
      name="gz::sim::systems::JointStatePublisher">
    </plugin>

    <plugin
      filename="gz-sim-diff-drive-system"
      name="gz::sim::systems::DiffDrive">
      <left_joint>left_drive_joint</left_joint>
      <right_joint>right_drive_joint</right_joint>
      <child_frame_id>robot/base_link</child_frame_id>
      <wheel_separation>0.26</wheel_separation>
      <wheel_radius>0.04</wheel_radius>
      <odom_publish_frequency>64</odom_publish_frequency>
    </plugin>
  </gazebo>

</robot>