<?xml version="1.0"?>
<robot name="simple_diff_drive">

  <material name="green">
    <color rgba="0 0.4 0.2 1"/>
  </material>
  <material name="dark_green">
    <color rgba="0 0.05 0 1"/>
  </material>
  <material name="light_green">
    <color rgba="0.9 1.0 0.9 1"/>
  </material>

  <link name="base_link">
    <visual>
      <geometry>
        <box size="0.6 0.5 0.3"/>
      </geometry>
    </visual>
  </link>

  <link name="right_drive_link">
    <visual>
      <geometry>
	<cylinder radius="0.08" length="0.04"/>
      </geometry>
    </visual>
  </link>

  <joint name="base_right_drive_joint" type="continuous">
    <parent link="base_link"/>
      <child link="right_drive_link"/>
      <origin xyz="-0.25 -0.25 -0.14" rpy="1.5708 0 0"/>
      <axis xyz="0 0 -2"/>
  </joint>

  <link name="left_drive_link">
    <visual>
      <geometry>
	<cylinder radius="0.08" length="0.04"/>
      </geometry>
      <material name="light_green"/>
    </visual>
    <collision>
      <geometry>
	<cylinder radius="0.08" length="0.04"/>
      </geometry>
    </collision>
    <inertial>
      <mass value="1"/>
      <inertia ixx="0.00045" ixy="0" ixz="0" iyy="0.00045" iyz="0" izz="0.0008"/>
    </inertial>
  </link>

  <joint name="base_left_drive_joint" type="continuous">
    <parent link="base_link"/>
      <child link="left_drive_link"/>
      <origin xyz="-0.25 0.25 -0.14" rpy="1.5708 0 0"/>
      <axis xyz="0 0 -2"/>
  </joint>

  <link name="front_driven_link">
    <visual>
      <geometry>
	<sphere radius="0.0446"/>
      </geometry>
    </visual>
    <collision>
      <geometry>
	<sphere radius="0.0446"/>
      </geometry>
    </collision>
    <inertial>
      <mass value="2"/>
      <inertia ixx="0.0016" ixy="0" ixz="0" iyy="0.0016" iyz="0" izz="0.0016"/>
    </inertial>
  </link>
	
  <joint name="base_driven_joint" type="fixed">
    <parent link="base_link"/>
    <child link="front_driven_link"/>
    <origin xyz="0.19 0 -0.18" rpy="0 0 0"/>
  </joint>

</robot>
